Workbook

Sheet 종합 요약 지급여부 0905
B2: 구분 | C2: 매출 | D2: 부가가치세 | L2: 구분 | M2: 매출 | N2: 부가가치세
B3: 글라스3 | C3: 10800 | D3: =C3*0.1 -> 1080 | L3: 글라스3 | M3: 10800 | N3: =M3*0.1 -> 1080
B4: 박스1 | C4: 4300 | D4: =C4*0.1 -> 430 | L4: 박스4 | M4: 17200 | N4: =M4*0.1 -> 1720
B5: 박스4 | C5: 17200 | D5: =C5*0.1 -> 1720 | E5: 9,10을 먼저 급여처리+장비 | L5: 박스1 | M5: 4300 | N5: =M5*0.1 -> 430
B6: 글라스4 | C6: 14400 | D6: =C6*0.1 -> 1440
B8: 26년 | L8: 27년
B9: 전환사업 | C9: 인건비 | D9: 사업비용 | E9: 장비 | F9: 법인세 | G9: 법인지방세 | H9: 잉여금 | L9: 전환사업 | M9: 유지보수 | N9: 고도화 | O9: 인건비 | P9: 기타사업? | Q9: 사업비용 | R9: 법인세 | S9: 법인지방세 | T9: 잉여금
B10: =C3+C4+C5+C6 -> 46700 | C10: =SUM(B13:K17) -> 23100 | D10: 400 | E10: 3000 | F10: =MIN(H10,20000)*10%+MAX(H10-20000,0)*20% -> 2040 | G10: =F10*0.1 -> 204 | H10: =B10-C10-D10-E10 -> 20200 | L10: =M3+M4+M5 -> 32300 | M10: 7700 | O10: =SUM(L13:W17) -> 21900 | Q10: 200 | R10: =MIN(T10,20000)*10%+MAX(T10-20000,0)*20% -> 1790 | S10: =R10*0.1 -> 179 | T10: =L10+M10+N10-O10-Q10 -> 17900
B11: 26 | L11: 27
B12: 4 | C12: 5 | D12: 6 | E12: 7 | F12: 8 | G12: 9 | H12: 10 | I12: 11 | J12: 12 | K12: 성과금(26) | L12: 1 | M12: 2 | N12: 3 | O12: 4 | P12: 5 | Q12: 6 | R12: 7 | S12: 8 | T12: 9 | U12: 10 | V12: 11 | W12: 12
A13: Y | B13: 600 | C13: 600 | D13: 600 | E13: 600 | F13: 600 | G13: 600 | H13: 600 | I13: 600 | J13: 600 | K13: 800 | L13: 600 | M13: 600 | N13: 600 | O13: 600 | P13: 600 | Q13: 600 | R13: 600 | S13: 600 | T13: 600 | U13: 600 | V13: 600 | W13: 600
B14: 700 | C14: 700 | D14: 700 | E14: 700 | F14: 700 | G14: 700 | H14: 700 | I14: 700 | J14: 700 | K14: 800 | L14: 700 | M14: 700 | N14: 700 | O14: 700 | P14: 700 | Q14: 700
B15: 600 | C15: 600 | D15: 600 | E15: 600 | F15: 600 | G15: 600 | H15: 600 | I15: 600 | J15: 600 | K15: 800 | L15: 700 | M15: 700 | N15: 700 | O15: 700 | P15: 700
A16: JY | G16: 700 | H16: 700 | I16: 700 | J16: 700 | K16: 800 | L16: 700 | M16: 700 | N16: 700 | O16: 700 | P16: 700
L17: 700 | M17: 700 | N17: 700 | O17: 700 | P17: 700
B20: 매출 | C20: =B10+L10+M10 -> 86700
B21: 법인세 + 비용 | C21: =D10+F10+Q10+R10+G10+S10 -> 4813
B22: 잉여금 | C22: =C20-C21 -> 81887 | E22: 26년 | F22: =SUM(B13:K17) -> 23100
B23: 평균 | C23: =C22/2 -> 40943.5 | E23: 27년 | F23: =SUM(L14:W17) -> 14700
E24: 장비 | F24: =E10 -> 3000
E25: 기타 | F25: 244 | G25: 갤럭시8
E26: 형 | F26: =F22+F23+F24+F25 -> 41044
E27: 대표 | F27: =C22-F26 -> 40843

Sheet 인건비 상세
A1: 인건비 상세 내역
A3: [ 2026년 인건비 ]
A4: 구분 | B4: 직원A | C4: 직원B | D4: 직원C | E4: 월 합계 | F4: 근무개월 | G4: 금액(만원)
A5: 월급(만원) | B5: 600 | C5: 600 | D5: 700 | E5: =SUM(B5:D5) -> 1900
A6: 근무기간 | B6: 4~9월 | C6: 4~9월 | D6: 4~9월 | F6: 6
A7: 기본급 합계 | E7: =E5 -> 1900 | F7: 6 | G7: =E7*F7 -> 11400
A8: 2026년 인건비 합계 | G8: =G7 -> 11400
A11: [ 2027년 인건비 ]
A12: 시기 | B12: 내용 | C12: 인원 | D12: 월급/월합 | E12: 개월 | F12: 금액(만원)
A13: 1월 | B13: 근무(3명) | C13: 3명 | D13: 1900 | E13: 1 | F13: =D13*E13 -> 1900
A14: 1월 | B14: 성과금(3개월치 추가지급) | C14: 3명 | D14: 1900×3 | F14: 5700
A15: 2~8월 | B15: 근무(3명) | C15: 3명 | D15: 1900 | E15: 7 | F15: =D15*E15 -> 13300
A16: 9~12월 | B16: 1명 계속근무 (나머지 계약종료) | C16: 1명 | D16: 600 | E16: 4 | F16: =D16*E16 -> 2400
A17: 2027년 인건비 합계 | F17: =SUM(F13:F16) -> 23300
A20: 매출 · 인건비 · 경비 · 법인세 종합 (단위: 억원)
A22: 구분 | B22: 매출 | C22: 인건비 | D22: 경비(장비) | E22: 과세표준 | F22: 법인세 | G22: 총부담(법인세+지방세) | I22: 26 | L22: 27
A23: 2026년 | B23: 3.23 | C23: =G8/10000 -> 1.14 | D23: - | E23: =B23-C23 -> 2.09 | F23: ='법인세 계산'!E4/10000 -> 0.218 | G23: ='법인세 계산'!G4/10000 -> 0.2398 | I23: 0.3 | J23: 3.6 | K23: =I23*J23 -> 1.08 | L23: 0.7 | M23: 3.6 | N23: =L23*M23 -> 2.52
A24: 2027년 | B24: 4.67 | C24: =F17/10000 -> 2.33 | D24: 0.2 | E24: =B24-C24-D24 -> 2.14 | F24: ='법인세 계산'!E5/10000 -> 0.228 | G24: ='법인세 계산'!G5/10000 -> 0.2508 | I24: 0.5 | J24: 4.3 | K24: =I24*J24 -> 2.15 | L24: 0.5 | M24: 4.3 | N24: =L24*M24 -> 2.15
A25: 합계 | B25: =B23+B24 -> 7.9 | C25: =C23+C24 -> 3.47 | D25: =D24 -> 0.2 | E25: =E23+E24 -> 4.23 | F25: =F23+F24 -> 0.446 | G25: =G23+G24 -> 0.4906
A28: 전체 매출 | B28: =B25 -> 7.9
A29: 잉여금(세후) | B29: =B28-F25*1.1 -> 7.4094
A30: 지급 | B30: =B29/2 -> 3.7047

Sheet 법인세 계산
A1: 법인세 계산 상세 (단위: 만원)
A3: 구분 | B3: 과세표준 | C3: 2억이하 10% | D3: 2억초과 20% | E3: 법인세 | F3: 지방소득세(10%) | G3: 총 부담
A4: 2026년 | B4: ='인건비 상세'!E23*10000 -> 20900 | C4: =MIN(B4,20000)*10% -> 2000 | D4: =MAX(B4-20000,0)*20% -> 180 | E4: =C4+D4 -> 2180 | F4: =E4*10% -> 218 | G4: =E4+F4 -> 2398
A5: 2027년 | B5: ='인건비 상세'!E24*10000 -> 21400 | C5: =MIN(B5,20000)*10% -> 2000 | D5: =MAX(B5-20000,0)*20% -> 280 | E5: =C5+D5 -> 2280 | F5: =E5*10% -> 228 | G5: =E5+F5 -> 2508
A6: 합계 | B6: =B4+B5 -> 42300 | C6: =C4+C5 -> 4000 | D6: =D4+D5 -> 460 | E6: =E4+E5 -> 4460 | F6: =F4+F5 -> 446 | G6: =G4+G5 -> 4906
A8: ※ 전제 조건
A9: - 비용은 인건비·장비만 반영 (임대료·재료비·4대보험 회사부담분 등 미반영)
A10: - 장비 0.2억은 당해 전액 비용 처리
A11: - 세액공제·감면 미반영, 2026년 개정 법인세율 적용 (2억 이하 10% / 2억~200억 20%)
A12: - 과세표준 = 매출 - 인건비 - 경비

Sheet 정리(검토)
A1: 법인세·잉여금 정리 (단위: 만원)
A2: 기준: 첫 시트(종합 요약 지급여부 0905)의 값을 수식으로 참조합니다. 첫 시트를 고치면 이 시트도 자동으로 바뀝니다. (작성 2026-10-02)
A3: 글자색: 파랑 = 직접 입력한 전제값 / 초록 = 첫 시트 참조 / 검정 = 계산식
A5: 1. 연도별 손익·법인세
A6: 구분 | B6: 2026년 | C6: 2027년 | D6: 합계 | E6: 비고
A7: 매출 - 전환사업 | B7: ='종합 요약 지급여부 0905'!B10 -> 46700 | C7: ='종합 요약 지급여부 0905'!L10 -> 32300 | D7: =B7+C7 -> 79000 | E7: 26년: 글라스3·박스1·박스4·글라스4 / 27년: 글라스3·박스4·박스1. 세금계산서 발행 연도와 맞는지 확인 필요
A8: 매출 - 유지보수 | B8: 0 | C8: ='종합 요약 지급여부 0905'!M10 -> 7700 | D8: =B8+C8 -> 7700 | E8: 26년은 첫 시트에 유지보수 항목이 없어 0으로 입력
A9: 매출 - 고도화 | B9: 0 | C9: ='종합 요약 지급여부 0905'!N10 -> 0 | D9: =B9+C9 -> 0 | E9: 첫 시트 C20(매출 합계)에는 고도화(N10)가 빠져 있음. 값이 생기면 여기에는 반영됨
A10: 매출 합계 | B10: =SUM(B7:B9) -> 46700 | C10: =SUM(C7:C9) -> 40000 | D10: =B10+C10 -> 86700
A11: 인건비 | B11: ='종합 요약 지급여부 0905'!C10 -> 23100 | C11: ='종합 요약 지급여부 0905'!O10 -> 21900 | D11: =B11+C11 -> 45000 | E11: 성과금(26)·Y행 포함 전체. 전원 계약직, 4대보험 없음 (사용자 확인 2026-10-02)
A12: 사업비용 | B12: ='종합 요약 지급여부 0905'!D10 -> 400 | C12: ='종합 요약 지급여부 0905'!Q10 -> 200 | D12: =B12+C12 -> 600
A13: 장비 | B13: ='종합 요약 지급여부 0905'!E10 -> 3000 | C13: 0 | D13: =B13+C13 -> 3000 | E13: 당해 전액 비용 처리 전제. 27년은 첫 시트에 장비 항목이 없어 0으로 입력
A14: 비용 합계 | B14: =SUM(B11:B13) -> 26500 | C14: =SUM(C11:C13) -> 22100 | D14: =B14+C14 -> 48600
A15: 과세표준 (매출 - 비용) | B15: =B10-B14 -> 20200 | C15: =C10-C14 -> 17900 | D15: =B15+C15 -> 38100 | E15: 첫 시트 G10·S10(잉여금)과 같은 값. 2억원 초과분에는 20% 세율 적용
A16: 법인세 | B16: =MIN(MAX(B15,0),$B$32)*$B$33+MAX(B15-$B$32,0)*$B$34 -> 2040 | C16: =MIN(MAX(C15,0),$B$32)*$B$33+MAX(C15-$B$32,0)*$B$34 -> 1790 | D16: =B16+C16 -> 3830 | E16: 첫 시트 F10·R10과 같은 값
A17: 지방소득세 | B17: =B16*$B$35 -> 204 | C17: =C16*$B$35 -> 179 | D17: =B17+C17 -> 383 | E17: 첫 시트에는 반영되어 있지 않음
A18: 세금 합계 | B18: =B16+B17 -> 2244 | C18: =C16+C17 -> 1969 | D18: =B18+C18 -> 4213
A19: 기타 지출 (갤럭시8) | B19: ='종합 요약 지급여부 0905'!F25 -> 244 | C19: 0 | D19: =B19+C19 -> 244 | E19: 과세표준에는 넣지 않음. 법인 명의·업무용이면 비용 처리 가능 → 세무사 확인
A20: 세후 잉여금 | B20: =B15-B18-B19 -> 17712 | C20: =C15-C18-C19 -> 15931 | D20: =B20+C20 -> 33643 | E20: 과세표준 - 세금 합계 - 기타 지출
A21: 세후 잉여금 (억원) | B21: =B20/10000 -> 1.7712 | C21: =C20/10000 -> 1.5931 | D21: =D20/10000 -> 3.3643
A23: 2. 첫 시트 최종 잉여금(C24)과 차이 나는 이유
A24: 첫 시트 최종 잉여금 (C24) | B24: ='종합 요약 지급여부 0905'!C24 -> 0
A25: (-) 첫 시트 잉여금 계산(F22·F23)에서 빠진 인건비 | B25: =('종합 요약 지급여부 0905'!C10+'종합 요약 지급여부 0905'!O10)-('종합 요약 지급여부 0905'!F22+'종합 요약 지급여부 0905'!F23) -> 7200 | E25: 첫 시트 F22·F23의 범위가 세금 계산용 인건비(C10·O10)와 같으면 0
A26: (-) 지방소득세 | B26: =D17 -> 383 | E26: 첫 시트 법인세(F10·R10)에 지방소득세가 없음
A27: 이 시트 세후 잉여금 | B27: =B24-B25-B26 -> -7583
A28: 검산 (0이어야 함) | B28: =B27-D20 -> -41226 | E28: 2번 표 결과 - 1번 표 세후 잉여금 합계(D20)
A31: 3. 세율 전제
A32: 낮은 세율 구간 상한 (만원) | B32: 20000 | E32: 과세표준 2억원. 2026.1.1 이후 개시 사업연도부터 적용 (2025.12 국회 통과)
A33: 법인세율 - 2억 이하 | B33: 0.1 | E33: 출처: KPMG 2025 Tax Reform, 커넥트 세무회계 (2026-10-02 검색 확인)
A34: 법인세율 - 2억 초과 200억 이하 | B34: 0.2
A35: 지방소득세 (법인세 대비) | B35: 0.1 | E35: 과세표준의 1.0% / 2.0% = 법인세의 10%. 출처: 법무법인 태평양 2026년 개정 지방세법 (2026-10-02 검색 확인)
A37: 4. 전제·확인 필요 사항
A38: ① 인건비: 전원 계약직, 4대보험 없음(사용자 확인). 단 근로계약(계약직 근로자)이면 4대보험·퇴직금 대상이고, 3.3% 용역(프리랜서) 계약일 때만 해당 없음 → 계약 형태 확인 필요
A39: ② 매출 귀속: 입금일이 아니라 세금계산서 발행(용역 제공) 연도 기준. 26년/27년 배분이 실제 발행 일정과 맞는지 확인
A40: ③ 장비: PC·주변기기는 당해 전액 비용 가능(법인세법 시행령 제31조), 그 외 장비는 건당 100만원 초과 시 감가상각으로 나눠야 함
A41: ④ 갤럭시8(기타 지출): 현재 과세표준에 미반영. 법인 명의·업무용이면 비용 처리 가능
A42: ⑤ 세액감면·공제(중소기업 특별세액감면, 창업·고용 관련)는 미반영. 해당되면 세금이 줄어듦
A43: ⑥ '인건비 상세'·'법인세 계산' 시트는 매출 배분·인건비·장비 연도가 첫 시트와 달라 이 시트와 숫자가 다름
A44: ⑦ Y는 비용으로 봄(사용자 확인 2026-10-02). 첫 시트 F23을 =SUM(L13:W17)로 수정해 Y의 27년 급여를 반영함
A46: 5. 5:5 점검 (비용 합계 : 세후 잉여금)
...
